<?xml version="1.0"?>
<robot name="my_robot">

  <material name="black"><color rgba="0.0 0.0 0.0 1.0"/></material>
  <material name="blue"><color rgba="0.0 0.0 1.0 1.0"/></material>
  <material name="green"><color rgba="0.0 1.0 0.0 1.0"/></material>
  <material name="red"><color rgba="1.0 0.0 0.0 1.0"/></material>
  <material name="grey"><color rgba="0.5 0.5 0.5 1.0"/></material>

  <link name="base_footprint"/>

  <link name="base_link">
    <visual>
      <origin xyz="0 0 0.10" rpy="0 0 0"/>
      <geometry><box size="0.40 0.25 0.16"/></geometry>
      <material name="blue"/>
    </visual>
    <collision>
      <origin xyz="0 0 0.10" rpy="0 0 0"/>
      <geometry><box size="0.40 0.25 0.16"/></geometry>
    </collision>
    <inertial>
      <mass value="10.0"/>
      <origin xyz="0 0 0.10"/>
      <inertia ixx="0.20" iyy="0.20" izz="0.35" ixy="0" ixz="0" iyz="0"/>
    </inertial>
  </link>

  <joint name="base_joint" type="fixed">
    <parent link="base_footprint"/>
    <child  link="base_link"/>
    <origin xyz="0 0 0"/>
  </joint>

  <link name="left_wheel">
    <visual>
      <origin xyz="0 0 0" rpy="1.5708 0 0"/>
      <geometry><cylinder length="0.04" radius="0.065"/></geometry>
      <material name="black"/>
    </visual>
    <collision>
      <origin xyz="0 0 0" rpy="1.5708 0 0"/>
      <geometry><cylinder length="0.04" radius="0.065"/></geometry>
    </collision>
    <inertial>
      <mass value="0.3"/>
      <inertia ixx="0.0004" iyy="0.0004" izz="0.0006" ixy="0" ixz="0" iyz="0"/>
    </inertial>
  </link>

  <joint name="left_wheel_joint" type="continuous">
    <parent link="base_link"/>
    <child  link="left_wheel"/>
    <origin xyz="0.14 0.17 0.065" rpy="0 0 0"/>
    <axis xyz="0 1 0"/>
    <limit effort="100" velocity="10"/>
    <dynamics damping="0.1" friction="1.0"/>
  </joint>

  <link name="right_wheel">
    <visual>
      <origin xyz="0 0 0" rpy="1.5708 0 0"/>
      <geometry><cylinder length="0.04" radius="0.065"/></geometry>
      <material name="black"/>
    </visual>
    <collision>
      <origin xyz="0 0 0" rpy="1.5708 0 0"/>
      <geometry><cylinder length="0.04" radius="0.065"/></geometry>
    </collision>
    <inertial>
      <mass value="0.3"/>
      <inertia ixx="0.0004" iyy="0.0004" izz="0.0006" ixy="0" ixz="0" iyz="0"/>
    </inertial>
  </link>

  <joint name="right_wheel_joint" type="continuous">
    <parent link="base_link"/>
    <child  link="right_wheel"/>
    <origin xyz="0.14 -0.17 0.065" rpy="0 0 0"/>
    <axis xyz="0 1 0"/>
    <limit effort="100" velocity="10"/>
    <dynamics damping="0.1" friction="1.0"/>
  </joint>

  <link name="contact_sphere">
    <collision>
      <origin xyz="0 0 0" rpy="0 0 0"/>
      <geometry><sphere radius="0.015"/></geometry>
    </collision>
    <inertial>
      <mass value="0.001"/>
      <inertia ixx="1e-8" iyy="1e-8" izz="1e-8" ixy="0" ixz="0" iyz="0"/>
    </inertial>
  </link>

  <joint name="contact_joint" type="fixed">
    <parent link="base_link"/>
    <child  link="contact_sphere"/>
    <origin xyz="-0.18 0 0.015" rpy="0 0 0"/>
  </joint>

  <gazebo reference="contact_sphere">
    <mu1>0.01</mu1>
    <mu2>0.01</mu2>
  </gazebo>

  <link name="lidar_link">
    <visual>
      <geometry><cylinder length="0.03" radius="0.04"/></geometry>
      <material name="red"/>
    </visual>
    <collision>
      <geometry><cylinder length="0.03" radius="0.04"/></geometry>
    </collision>
    <inertial>
      <mass value="0.05"/>
      <inertia ixx="0.00001" iyy="0.00001" izz="0.00001" ixy="0" ixz="0" iyz="0"/>
    </inertial>
  </link>

  <joint name="lidar_joint" type="fixed">
    <parent link="base_link"/>
    <child  link="lidar_link"/>
    <origin xyz="0.18 0 0.22" rpy="0 0 0"/>
  </joint>

  <gazebo reference="lidar_link">
    <sensor type="ray" name="lds_lidar">
      <pose>0 0 0 0 0 0</pose>
      <visualize>false</visualize>
      <update_rate>10</update_rate>
      <ray>
        <scan>
          <horizontal>
            <samples>360</samples>
            <resolution>1</resolution>
            <min_angle>-1.570796</min_angle>
            <max_angle>1.570796</max_angle>
          </horizontal>
        </scan>
        <range>
          <min>0.12</min>
          <max>10.0</max>
          <resolution>0.01</resolution>
        </range>
        <noise>
          <type>gaussian</type>
          <mean>0.0</mean>
          <stddev>0.01</stddev>
        </noise>
      </ray>
      <plugin name="gazebo_ros_lds_lidar" filename="libgazebo_ros_laser.so">
        <topicName>/scan</topicName>
        <frameName>lidar_link</frameName>
      </plugin>
    </sensor>
  </gazebo>

  <link name="camera_link">
    <visual>
      <geometry><box size="0.03 0.06 0.03"/></geometry>
      <material name="green"/>
    </visual>
    <collision>
      <geometry><box size="0.03 0.06 0.03"/></geometry>
    </collision>
    <inertial>
      <mass value="0.02"/>
      <inertia ixx="0.00001" iyy="0.00001" izz="0.00001" ixy="0" ixz="0" iyz="0"/>
    </inertial>
  </link>

  <joint name="camera_joint" type="fixed">
    <parent link="base_link"/>
    <child  link="camera_link"/>
    <origin xyz="0.22 0 0.24" rpy="0 0 0"/>
  </joint>

  <gazebo reference="camera_link">
    <sensor type="camera" name="rgb_camera">
      <update_rate>30.0</update_rate>
      <camera>
        <horizontal_fov>1.047198</horizontal_fov>
        <image>
          <width>640</width>
          <height>480</height>
          <format>R8G8B8</format>
        </image>
        <clip>
          <near>0.05</near>
          <far>10.0</far>
        </clip>
      </camera>
      <plugin name="gazebo_ros_camera" filename="libgazebo_ros_camera.so">
        <alwaysOn>true</alwaysOn>
        <updateRate>30.0</updateRate>
        <imageTopicName>/camera/rgb/image_raw</imageTopicName>
        <cameraInfoTopicName>/camera/rgb/camera_info</cameraInfoTopicName>
        <frameName>camera_link</frameName>
        <hackBaseline>0.07</hackBaseline>
        <distortionK1>0.0</distortionK1>
        <distortionK2>0.0</distortionK2>
        <distortionK3>0.0</distortionK3>
        <distortionT1>0.0</distortionT1>
        <distortionT2>0.0</distortionT2>
      </plugin>
    </sensor>
  </gazebo>

  <gazebo>
    <plugin name="gazebo_ros_diff_drive" filename="libgazebo_ros_diff_drive.so">
      <numWheelPairs>1</numWheelPairs>
      <leftJoint>left_wheel_joint</leftJoint>
      <rightJoint>right_wheel_joint</rightJoint>
      <wheelSeparation>0.34</wheelSeparation>
      <wheelDiameter>0.13</wheelDiameter>
      <wheelTorque>50</wheelTorque>
      <wheelAcceleration>2.0</wheelAcceleration>
      <commandTopic>/cmd_vel</commandTopic>
      <odometryTopic>/odom</odometryTopic>
      <odometryFrame>odom</odometryFrame>
      <robotBaseFrame>base_footprint</robotBaseFrame>
      <publishWheelTF>false</publishWheelTF>
      <publishOdomTF>true</publishOdomTF>
      <publishWheelJointState>true</publishWheelJointState>
      <updateRate>100.0</updateRate>
    </plugin>
  </gazebo>

  <gazebo>
    <plugin name="joint_state_publisher" filename="libgazebo_ros_joint_state_publisher.so">
      <updateRate>100.0</updateRate>
    </plugin>
  </gazebo>

</robot>